Workbook

Sheet BalansenWinstverlies - FY2018
A1: CodeAdministratie | B1: NaamAdministratie | C1: CodeDimensietype | D1: NaamDimensietype | E1: CodeRapportagestructuurgroep1 | F1: NaamRapportagestructuurgroep2 | G1: CodeRapportagestructuurgroep3 | H1: NaamRapportagestructuurgroep4 | I1: CodeRapportagestructuurgroep5 | J1: NaamRapportagestructuurgroep6 | K1: CodeGrootboekrekening | L1: NaamGrootboekrekening | M1: Saldo
A2: 041066359000 | B2: QSP ESS B.V. | C2: BAS | D2: Balans | E2: GLB15 | F2: Vastgoedbeleggingen | G2: SLB2510 | H2: Vastgoedbeleggingen | K2: 1600000 | L2: VG Vastgoedbeleggingen Verkrijgings- of vervaardigingsprijs | M2: 1.3492958e+08
A3: 041066359000 | B3: QSP ESS B.V. | C3: BAS | D3: Balans | E3: GLB15 | F3: Vastgoedbeleggingen | G3: SLB2510 | H3: Vastgoedbeleggingen | K3: 1600200 | L3: VG Vastgoedbeleggingen Cum afschrijvingen en waardeverm | M3: -8089661.7
A4: 041066359000 | B4: QSP ESS B.V. | C4: BAS | D4: Balans | E4: GLB15 | F4: Vastgoedbeleggingen | G4: SLB2510 | H4: Vastgoedbeleggingen | K4: 1610803 | L4: VG Comm VG in exploitatie Buitengebruikstellingen aanschaffingswaarde | M4: -2341968
A5: 041066359000 | B5: QSP ESS B.V. | C5: BAS | D5: Balans | E5: GLB20 | F5: Financiële vaste activa | G5: SLB2020 | H5: Overige deelneming | K5: 1710004 | L5: FVA Deelneming VvE portefeuille Vivare II | M5: -0.24
A6: 041066359000 | B6: QSP ESS B.V. | C6: BAS | D6: Balans | E6: GLB20 | F6: Financiële vaste activa | G6: SLB2100 | H6: Overige vorderingen | K6: 1790002 | L6: FVA Latente belastingvordering langlopend | M6: 2022416.4
A7: 041066359000 | B7: QSP ESS B.V. | C7: BAS | D7: Balans | E7: GLB40 | F7: Vorderingen | G7: SLB4010 | H7: Debiteuren | K7: 2000000 | L7: VOR Debiteuren | M7: 171593.69
A8: 041066359000 | B8: QSP ESS B.V. | C8: BAS | D8: Balans | E8: GLB40 | F8: Vorderingen | G8: SLB4010 | H8: Debiteuren | K8: 2000300 | L8: VOR Voorziening dubieuze debiteuren | M8: -14000
A9: 041066359000 | B9: QSP ESS B.V. | C9: BAS | D9: Balans | E9: GLB40 | F9: Vorderingen | G9: SLB4076 | H9: Rekening-courant aandeelhouder | K9: 2640000 | L9: RC Kortlopend DMRRP INV - I BV | M9: 110497
A10: 041066359000 | B10: QSP ESS B.V. | C10: BAS | D10: Balans | E10: GLB40 | F10: Vorderingen | G10: SLB4076 | H10: Rekening-courant aandeelhouder | K10: 2640001 | L10: RC Kortlopend QSPESS Limited | M10: 0
A11: 041066359000 | B11: QSP ESS B.V. | C11: BAS | D11: Balans | E11: GLB40 | F11: Vorderingen | G11: SLB4080 | H11: Overige vorderingen en overlopende activa | K11: 2040700 | L11: VOR Vooruitbetaalde servicekosten | M11: 0
A12: 041066359000 | B12: QSP ESS B.V. | C12: BAS | D12: Balans | E12: GLB40 | F12: Vorderingen | G12: SLB4080 | H12: Overige vorderingen en overlopende activa | K12: 2040900 | L12: VOR Vooruitbetaalde overige kosten | M12: 0
A13: 041066359000 | B13: QSP ESS B.V. | C13: BAS | D13: Balans | E13: GLB50 | F13: Liquide middelen | G13: SLB5020 | H13: Kruisposten | K13: 2300000 | L13: LM Kruisposten | M13: 0
... A33: 041066359000 | B33: QSP ESS B.V. | C33: BAS | D33: Balans | E33: GLB80 | F33: Kortlopende schulden | G33: SLB8025 | H33: Schulden aan lev en handelskred | K33: 2730001 | L33: KLS Crediteuren intercompany | M33: 0
A34: 041066359000 | B34: QSP ESS B.V. | C34: BAS | D34: Balans | E34: GLB80 | F34: Kortlopende schulden | G34: SLB8060 | H34: Belastingen en pensioen | I34: SLB80601 | J34: Omzetbelasting | K34: 2512100 | L34: BEL Afgedragen/ontvangen BTW | M34: -6845.46
A35: 041066359000 | B35: QSP ESS B.V. | C35: BAS | D35: Balans | E35: GLB80 | F35: Kortlopende schulden | G35: SLB8060 | H35: Belastingen en pensioen | I35: SLB80603 | J35: Vennootschapsbelasting | K35: 2530000 | L35: BEL Te betalen vennootschapsbelasting | M35: 536277
A36: 041066359000 | B36: QSP ESS B.V. | C36: BAS | D36: Balans | E36: GLB80 | F36: Kortlopende schulden | G36: SLB8060 | H36: Belastingen en pensioen | I36: SLB80606 | J36: Overige belastingen | K36: 2550000 | L36: BEL Te betalen overige belastingen | M36: 0
A37: 041066359000 | B37: QSP ESS B.V. | C37: BAS | D37: Balans | E37: GLB80 | F37: Kortlopende schulden | G37: SLB8065 | H37: Overige schulden | K37: 2740300 | L37: KLS Te betalen waarborgsommen kortlopend | M37: -666513.99
A38: 041066359000 | B38: QSP ESS B.V. | C38: BAS | D38: Balans | E38: GLB80 | F38: Kortlopende schulden | G38: SLB8065 | H38: Overige schulden | K38: 2740500 | L38: KLS Te betalen accountants- en administratiekosten | M38: -22500
A39: 041066359000 | B39: QSP ESS B.V. | C39: BAS | D39: Balans | E39: GLB80 | F39: Kortlopende schulden | G39: SLB8065 | H39: Overige schulden | K39: 2740600 | L39: KLS Te betalen rente | M39: 0
A40: 041066359000 | B40: QSP ESS B.V. | C40: BAS | D40: Balans | E40: GLB80 | F40: Kortlopende schulden | G40: SLB8065 | H40: Overige schulden | K40: 2741000 | L40: KLS Te betalen servicekosten | M40: -18117.02
A41: 041066359000 | B41: QSP ESS B.V. | C41: BAS | D41: Balans | E41: GLB80 | F41: Kortlopende schulden | G41: SLB8065 | H41: Overige schulden | K41: 2741001 | L41: KLS Te betalen exploitatiekosten | M41: 0
A42: 041066359000 | B42: QSP ESS B.V. | C42: BAS | D42: Balans | E42: GLB80 | F42: Kortlopende schulden | G42: SLB8065 | H42: Overige schulden | K42: 2741002 | L42: KLS Te betalen VVE | M42: 0
A43: 041066359000 | B43: QSP ESS B.V. | C43: BAS | D43: Balans | E43: GLB80 | F43: Kortlopende schulden | G43: SLB8065 | H43: Overige schulden | K43: 2741003 | L43: KLS Te betalen Wieglia | M43: 0
A44: 041066359000 | B44: QSP ESS B.V. | C44: BAS | D44: Balans | E44: GLB80 | F44: Kortlopende schulden | G44: SLB8065 | H44: Overige schulden | K44: 2741004 | L44: KLS Te betalen Hoen | M44: -40157.89
A45: 041066359000 | B45: QSP ESS B.V. | C45: BAS | D45: Balans | E45: GLB80 | F45: Kortlopende schulden | G45: SLB8065 | H45: Overige schulden | K45: 2741005 | L45: KLS Te betalen managementvergoedingen | M45: 0
A46: 041066359000 | B46: QSP ESS B.V. | C46: BAS | D46: Balans | E46: GLB80 | F46: Kortlopende schulden | G46: SLB8065 | H46: Overige schulden | K46: 2741200 | L46: KLS Te betalen overige kosten | M46: -5040
A47: 041066359000 | B47: QSP ESS B.V. | C47: BAS | D47: Balans | E47: GLB80 | F47: Kortlopende schulden | G47: SLB8065 | H47: Overige schulden | K47: 2741900 | L47: KLS Nog uit te zoeken posten MT940 | M47: 918.63
A48: 041066359000 | B48: QSP ESS B.V. | C48: BAS | D48: Balans | E48: GLB80 | F48: Kortlopende schulden | G48: SLB8065 | H48: Overige schulden | K48: 2742200 | L48: KLS Vooruitontvangen bedragen | M48: -146910.69
... A59: 041066359000 | B59: QSP ESS B.V. | C59: PNL | D59: Winst & verlies | E59: GLP20 | F59: Bedrijfslasten | G59: SLP2025 | H59: Overige personeelskosten | K59: 4051400 | L59: KN Diensten door derden | M59: 472384.16
A60: 041066359000 | B60: QSP ESS B.V. | C60: PNL | D60: Winst & verlies | E60: GLP20 | F60: Bedrijfslasten | G60: SLP2030 | H60: Afschrijvingen | I60: SLP20303 | J60: Afschrijvingen VG | K60: 4730000 | L60: AFKN Afschrijvingskosten Vastgoedbeleggingen | M60: 2698591.7
A61: 041066359000 | B61: QSP ESS B.V. | C61: PNL | D61: Winst & verlies | E61: GLP20 | F61: Bedrijfslasten | G61: SLP2030 | H61: Afschrijvingen | I61: SLP20303 | J61: Afschrijvingen VG | K61: 4730200 | L61: AFKN Boekresultaat Vastgoedbeleggingen | M61: -1219532
A62: 041066359000 | B62: QSP ESS B.V. | C62: PNL | D62: Winst & verlies | E62: GLP20 | F62: Bedrijfslasten | G62: SLP2040 | H62: Huisvestingskosten | K62: 4100400 | L62: KN Onderhoud gebouwen | M62: 1015338.5
A63: 041066359000 | B63: QSP ESS B.V. | C63: PNL | D63: Winst & verlies | E63: GLP20 | F63: Bedrijfslasten | G63: SLP2040 | H63: Huisvestingskosten | K63: 4100410 | L63: Verhuurdersheffing | M63: 568182
A64: 041066359000 | B64: QSP ESS B.V. | C64: PNL | D64: Winst & verlies | E64: GLP20 | F64: Bedrijfslasten | G64: SLP2040 | H64: Huisvestingskosten | K64: 4100900 | L64: KN Onroerende zaakbelasting | M64: 316136.1
A65: 041066359000 | B65: QSP ESS B.V. | C65: PNL | D65: Winst & verlies | E65: GLP20 | F65: Bedrijfslasten | G65: SLP2040 | H65: Huisvestingskosten | K65: 4101000 | L65: KN VvE-kosten | M65: 630780.63
A66: 041066359000 | B66: QSP ESS B.V. | C66: PNL | D66: Winst & verlies | E66: GLP20 | F66: Bedrijfslasten | G66: SLP2040 | H66: Huisvestingskosten | K66: 4101010 | L66: Gemeentelijke belastingen | M66: 1026.53
A67: 041066359000 | B67: QSP ESS B.V. | C67: PNL | D67: Winst & verlies | E67: GLP20 | F67: Bedrijfslasten | G67: SLP2040 | H67: Huisvestingskosten | K67: 4101020 | L67: Waterschapsbelasting | M67: 116470.82
A68: 041066359000 | B68: QSP ESS B.V. | C68: PNL | D68: Winst & verlies | E68: GLP20 | F68: Bedrijfslasten | G68: SLP2040 | H68: Huisvestingskosten | K68: 4101400 | L68: KN Kosten vereniging van eigenaren | M68: 0
A69: 041066359000 | B69: QSP ESS B.V. | C69: PNL | D69: Winst & verlies | E69: GLP20 | F69: Bedrijfslasten | G69: SLP2050 | H69: Verkoopkosten | K69: 4501300 | L69: KN Afboeking dubieuze debiteuren | M69: 1215.23
...

Sheet Cijfers QSP - Q1 2019
C2: Beginbalans (01-04-2018) | E2: Balans per 30-06-2018 | H2: Balans per 30-09-2018 | K2: Balans per 31-12-2018 | P2: Balans per 31-03-2019
A3: Balans
A4: 1600000 | B4: VG Vastgoedbeleggingen Verkrijgings- of vervaardigingsprijs | C4: 1.3492958e+08 | E4: =C4 -> 1.3492958e+08 | H4: =E4 -> 1.3492958e+08 | K4: 1.3492958e+08 | P4: 134929585
A5: 1600200 | B5: VG Vastgoedbeleggingen Cum afschrijvingen en waardeverm | C5: -6065717.9 | E5: =C5-556672.89 -> -6622390.8 | H5: =E5-556672.89 -> -7179063.7 | K5: -8089661.7 | P5: -8764309.7
A6: 1610803 | B6: VG Comm VG in exploitatie Buitengebruikstellingen aanschaffingswaarde | K6: -2341968 | P6: -2967534
A7: Totaal Vastgoedbeleggingen | C7: =SUM(C4:C6) -> 1.2886387e+08 | E7: =SUM(E4:E6) -> 1.2830719e+08 | H7: =SUM(H4:H6) -> 1.2775052e+08 | K7: =SUM(K4:K6) -> 1.2449795e+08 | P7: =SUM(P4:P6) -> 1.2319774e+08
A9: 1790002 | B9: FVA Latente belastingvordering langlopend | C9: 1516430 | E9: =C9 -> 1516430 | H9: =E9+139168.22 -> 1655598.2 | K9: 2051910.2 | P9: 2220572.2
A10: Totaal Financiële vaste activa | C10: =SUM(C9) -> 1516430 | E10: =SUM(E9) -> 1516430 | H10: =SUM(H9) -> 1655598.2 | K10: =SUM(K9) -> 2051910.2 | P10: =SUM(P9) -> 2220572.2
A12: 2000000 | B12: VOR Debiteuren | C12: 101970.5 | E12: =C12+142289.81 -> 244260.31 | H12: =E12+271621.52 -> 515881.83 | K12: 171593.69 | P12: 329178.26
A13: 2000300 | B13: VOR Voorziening dubieuze debiteuren | C13: -14000 | E13: =C13 -> -14000 | H13: =E13 -> -14000 | K13: -14000 | P13: -14000
A14: Totaal Debiteuren | C14: =SUM(C12:C13) -> 87970.5 | E14: =SUM(E12:E13) -> 230260.31 | H14: =SUM(H12:H13) -> 501881.83 | K14: =SUM(K12:K13) -> 157593.69 | P14: =SUM(P12:P13) -> 315178.26
A16: 2040700 | B16: VOR Vooruitbetaalde servicekosten | C16: 29258.85 | E16: 0 | H16: 0 | K16: 0 | P16: 0
A17: 2040900 | B17: VOR Vooruitbetaalde overige kosten | C17: 51218.7 | E17: 0 | H17: 0 | K17: 0 | P17: 0
A18: Totaal Overige vorderingen en overlopende activa | C18: =SUM(C16:C17) -> 80477.55 | E18: =SUM(E16:E17) -> 0 | H18: =SUM(H16:H17) -> 0 | K18: =SUM(K16:K17) -> 0 | P18: =SUM(P16:P17) -> 0
A20: 2640000 | B20: RC Kortlopend DMRRP INV - I BV | C20: 510497 | E20: =C20-400000 -> 110497 | H20: =E20 -> 110497 | K20: 110497 | P20: 110497
A21: Totaal Rekening-courant aandeelhouder | C21: =C20 -> 510497 | E21: =E20 -> 110497 | H21: =H20 -> 110497 | K21: =K20 -> 110497 | P21: =P20 -> 110497
A23: 2300000 | B23: LM Kruisposten | C23: 0 | E23: 0 | H23: 0 | K23: 0 | P23: 671.55
A24: 2400200 | B24: LM ABN AMRO Bank Disposal NL58 ABNA 0818 9180 39 | C24: 0 | E24: 985.82 | H24: =E24+2403985.53 -> 2404971.3 | K24: 986584.53 | P24: 538961.82
A25: 2400201 | B25: LM ABN AMRO Bank Deposit NL57 ABNA 0541 6205 68 | C25: 17365.7 | E25: =C25+101804.22 -> 119169.92 | H25: =E25-101349.86 -> 17820.06 | K25: 9648.09 | P25: 1369615.4
A26: 2400202 | B26: LM ABN AMRO Bank General NL93 ABNA 0541 6132 27 | C26: 116513.7 | E26: =C26-9646.52 -> 106867.18 | H26: =E26-83687.36 -> 23179.82 | K26: 191789.66 | P26: 1034628.1
A27: 2400203 | B27: LM ABN AMRO Bank Maintres NL04 ABNA 0541 6188 06 | C27: 12.23 | E27: =C27+654441.82 -> 654454.05 | H27: =E27-219333.49 -> 435120.56 | K27: 491535.05 | P27: 601349.86
A28: 2400204 | B28: LM ABN AMRO Bank Rent NL46 ABNA 0541 6088 35 | C28: 290930.72 | E28: =C28-416085.32 -> -125154.6 | H28: =E28+374178.16 -> 249023.56 | K28: 415424.01 | P28: 499735.95
A29: 2400205 | B29: LM ABN AMRO Bank SR EXP NL88 ABNA 0541 6205 92 | C29: 10983.92 | E29: =C29+200327.39 -> 211311.31 | H29: =E29-61914.41 -> 149396.9 | K29: 275171.2 | P29: 58139.79
A30: Totaal Liquide middelen | C30: =SUM(C23:C29) -> 435806.27 | E30: =SUM(E23:E29) -> 967633.68 | H30: =SUM(H23:H29) -> 3279512.2 | K30: =SUM(K23:K29) -> 2370152.5 | P30: =SUM(P23:P29) -> 4103102.5
A32: 1000002 | B32: EV Normale aandelen Saldo | C32: -1 | E32: =C32 -> -1 | H32: =E32 -> -1 | K32: -1 | P32: -1
A33: 1100000 | B33: EV Agioreserve Agio aandelen | C33: -19431219 | E33: =C33 -> -19431219 | H33: =E33 -> -19431219 | K33: -19431219 | P33: -19431219
A34: 1160000 | B34: EV Overige reserve Reserve aandelen | C34: =9890198.2+417450.68 -> 10307649 | E34: =C34 -> 10307649 | H34: =E34 -> 10307649 | K34: 9890198.2 | P34: 16135048
A35: 1160100 | B35: EV Overige reserve Dividenduitkeringen aandelen | C35: 0 | E35: 7497104.1 | H35: 7497104.1 | K35: 7727104.1 | P35: 310000
A36: Totaal Eigen vermogen | C36: =SUM(C32:C35) -> -9123571.6 | E36: =SUM(E32:E35) -> -1626467.5 | H36: =SUM(H32:H35) -> -1626467.5 | K36: =SUM(K32:K35) -> -1813918.2 | P36: =SUM(P32:P35) -> -2986172.5
P37: 0
A38: 1930000 | B38: LLS Hoofdsom ABN AMRO Bank NV leningen | C38: -86326750 | E38: 0 | H38: 0 | K38: 0 | P38: -130000000
A39: 1930001 | B39: LLS Hoofdsom ABN AMRO Bank NV Senior Facility Agreement | C39: 0 | E39: -130000000 | H39: -130000000 | K39: -130000000 | P39: 0
A40: 1930100 | B40: LLS Cum aflossingen ABN AMRO Bank NV leningen | C40: 759062.18 | E40: 0 | H40: 0 | K40: 0 | P40: 5070232.5
A41: 1930101 | B41: LLS Cum aflossingen ABN AMRO Bank NV Senior Facility Agreement | C41: 0 | E41: 812500 | H41: =E41+812500 -> 1625000 | K41: 5070232.5 | P41: 0
A42: 1930201 | B42: LLS Kortlopend deel ABN AMRO Bank NV Senior Facility Agreement | C42: 0 | E42: =C42 -> 0 | H42: =E42 -> 0 | K42: -306833.59
P43: 0
A44: 1990001 | B44: LLS Hoofdsom QSPESS Limited | C44: -35257825 | E44: 0 | H44: 0 | K44: 0
A45: Totaal Langlopende schulden | C45: =SUM(C38:C44) -> -1.2082551e+08 | E45: =SUM(E38:E44) -> -129187500 | H45: =SUM(H38:H44) -> -128375000 | K45: =SUM(K38:K44) -> -1.252366e+08 | P45: =SUM(P38:P44) -> -1.2492977e+08
P46: -22162.98
A47: 2730000 | B47: KLS Crediteuren | C47: -143296.28 | E47: =C47+137851.28 -> -5445 | H47: =E47+5444.99 -> -0.01 | K47: -9075.01 | P47: 0
...

Sheet BDO - Q2 2019
C1: Mutaties Q1 2019 | D1: Mutaties Q2 2019 | E1: Saldi per 30-06-2019
A3: Balans | C3: 0 | D3: 0
A4: 1600000 | B4: VG Vastgoedbeleggingen Verkrijgings- of vervaardigingsprijs | C4: -662362 | D4: -650161 | E4: 132164783
A5: 1600200 | B5: VG Vastgoedbeleggingen Cum afschrijvingen en waardeverm | C5: -651550 | D5: -1011554 | E5: -10634612 | G5: =E5+E6+E83 -> -7636718
A6: 1610803 | B6: VG Comm VG in exploitatie Buitengebruikstellingen aanschaffingswaarde | C6: 41286 | D6: 71536 | E6: 233092
A7: Totaal Vastgoedbeleggingen | C7: =SUM(C3:C6) -> -1272626 | D7: =SUM(D3:D6) -> -1590179 | E7: 121763263
A9: 1710004 | B9: FVA Deelneming VvE Portefeuille Vivare II
A10: 1790002 | B10: FVA Latente belastingvordering langlopend | C10: 168662 | D10: 142232 | E10: 2706901
A11: Totaal Financiële vaste activa | D11: =SUM(D9:D10) -> 142232 | E11: 2706901
A13: 2000000 | B13: VOR Debiteuren | C13: 157585 | D13: 66045 | E13: 342834
A14: 2000300 | B14: VOR Voorziening dubieuze debiteuren | C14: 0 | D14: 0 | E14: -64501
A15: Totaal Debiteuren | C15: =SUM(C13:C14) -> 157585 | D15: =SUM(D13:D14) -> 66045 | E15: 278333
A17: 2040700 | B17: VOR Vooruitbetaalde servicekosten | C17: 0 | D17: 0 | E17: 15594
A18: 2040900 | B18: VOR Vooruitbetaalde overige kosten | C18: 0 | D18: 0 | E18: 737
A19: Totaal overige vorderingen | C19: =SUM(C17:C18) -> 0 | D19: =SUM(D17:D18) -> 0 | E19: 16331
A21: 2640000 | B21: RC Kortlopend DMRRP INV - I BV | C21: 0 | D21: 0 | E21: 110497
A22: Totaal Rekening-courant aandeelhouder | C22: =SUM(C21) -> 0 | D22: =SUM(D21) -> 0 | E22: 110497
A24: 2300000 | B24: LM Kruisposten | C24: 672 | D24: -672 | E24: 0
A25: 2400200 | B25: LM ABN AMRO Bank Disposal NL58 ABNA 0818 9180 39 | C25: -447623 | D25: -458920 | E25: 80042
A26: 2400201 | B26: LM ABN AMRO Bank Deposit NL57 ABNA 0541 6205 68 | C26: 1359967 | D26: -1368856 | E26: 759
A27: 2400202 | B27: LM ABN AMRO Bank General NL93 ABNA 0541 6132 27 | C27: 842838 | D27: -1028597 | E27: 6031
A28: 2400203 | B28: LM ABN AMRO Bank Maintres NL04 ABNA 0541 6188 06 | C28: 109815 | D28: 44887 | E28: 646236
A29: 2400204 | B29: LM ABN AMRO Bank Rent NL46 ABNA 0541 6088 35 | C29: 84312 | D29: 528567 | E29: 1028303
A30: 2400205 | B30: LM ABN AMRO Bank SR EXP NL88 ABNA 0541 6205 92 | C30: -217031 | D30: 58399 | E30: 116539
A31: Totaal Liquide middelen | C31: =SUM(C25:C30) -> 1732278 | D31: =SUM(D25:D30) -> -2224520 | E31: 1877910
A33: 1000002 | B33: EV Normale aandelen Saldo | C33: 0 | D33: 0 | E33: -1
A34: 1100000 | B34: EV Agioreserve Agio aandelen | C34: 0 | D34: 0 | E34: -19431219
A35: 1160000 | B35: EV Overige reserve Reserve aandelen | C35: 0 | D35: 0 | E35: 11244686
A36: 1160100 | B36: EV Overige reserve Dividenduitkeringen aandelen | C36: 310000 | D36: 225000 | E36: 8262104
A37: Totaal Eigen vermogen | C37: =SUM(C33:C36) -> 310000 | D37: =SUM(D33:D36) -> 225000 | E37: 75570
A39: 1930001 | B39: LLS Hoofdsom ABN AMRO Bank NV Senior Facility Agreement | C39: 0 | D39: 0 | E39: -130000000
A40: 1930101 | B40: LLS Cum aflossingen ABN AMRO Bank NV Senior Facility Agreement | C40: 0 | D40: 4692972 | E40: 9763205
A41: 1930201 | B41: LLS Kortlopend deel ABN AMRO Bank NV Senior Facility Agreement | C41: 306834 | D41: 0 | E41: 0
A42: Totaal Langlopende schulden | C42: =SUM(C39:C41) -> 306834 | D42: =SUM(D39:D41) -> 4692972 | E42: -120236795
A44: 2730000 | B44: KLS Crediteuren | C44: -18824 | D44: 27899 | E44: -167794
A45: 2730001 | B45: KLS Crediteuren intercompany | C45: 0 | D45: 0 | E45: 0
A46: Totaal Crediteuren | C46: =SUM(C44:C45) -> -18824 | D46: =SUM(D44:D45) -> 27899 | E46: -167794
A48: 2511000 | B48: BEL BTW te vorderen hoog | D48: 0 | E48: 0
A49: 2512100 | B49: BEL Afgedragen/ontvangen BTW | C49: 4150 | D49: 9 | E49: -3707
A50: 2530000 | B50: BEL Te betalen vennootschapsbelasting | C50: 0 | D50: -197342 | E50: -528792
...

Sheet BDO - Q3 2019
C1: Eindbalans 30-09-2018 | D1: Mutaties periode Q4 2018 | E1: Mutaties Q1 t/m Q3 2019 | F1: Saldi per 30-09-2019 | H1: Mutaties Q3 2019
A3: Balans
A4: 1600200 | B4: VG Vastgoedbeleggingen Verkrijgings- of vervaardigingsprijs | C4: 134929585 | D4: -2259117 | E4: 0 | F4: =SUM(C4:E4) -> 132670468 | H4: 0
A5: 1600200 | B5: VG Vastgoedbeleggingen Cum afschrijvingen en waardeverm | C5: =-7179064 -> -7179064 | D5: -895606 | E5: -1966185 | F5: =SUM(C5:E5) -> -10040855 | H5: -653662
A6: 1610803 | B6: VG Comm VG in exploitatie Buitengebruikstellingen aanschaffingswaarde | E6: -2215390 | F6: =SUM(C6:E6) -> -2215390 | H6: -462286
A7: 1611003 | B7: VG Comm VG in exploitatie Buitengebruikstellingen cum. afschr. en waardeverm. | C7: 83981 | D7: 36289 | E7: 146755 | F7: =SUM(C7:E7) -> 267025 | H7: 33933
A8: Totaal Vastgoedbeleggingen | C8: =SUM(C4:C7) -> 127834502 | D8: =SUM(D4:D7) -> -3118434 | E8: =SUM(E4:E7) -> -4034820 | F8: =SUM(C8:E8) -> 120681248 | H8: =SUM(H4:H7) -> -1082015
A10: 1790002 | B10: FVA Latente belastingvordering langlopend | C10: 1655598 | D10: 740409 | E10: 464688 | F10: =SUM(C10:E10) -> 2860695 | H10: 153794
A11: Totaal Financiële vaste activa | C11: =SUM(C10) -> 1655598 | D11: =SUM(D10) -> 740409 | E11: =SUM(E10) -> 464688 | F11: =SUM(C11:E11) -> 2860695 | H11: =SUM(H10) -> 153794
A13: 2000000 | B13: VOR Debiteuren | C13: =515882-177000-115000 -> 223882 | D13: =-396678+177000+115000 -> -104678 | E13: 130719 | F13: =SUM(C13:E13) -> 249923 | H13: -93669
A14: 2000300 | B14: VOR Voorziening dubieuze debiteuren | C14: -14000 | D14: -50501 | F14: =SUM(C14:E14) -> -64501 | H14: 0
A15: Totaal Debiteuren | C15: =SUM(C13:C14) -> 209882 | D15: =SUM(D13:D14) -> -155179 | E15: =SUM(E13:E14) -> 130719 | F15: =SUM(C15:E15) -> 185422 | H15: =SUM(H13:H14) -> -93669
A17: 2640000 | B17: RC Kortlopend DMRRP INV - I BV | C17: 110497 | D17: 0 | E17: 0 | F17: =SUM(C17:E17) -> 110497 | H17: 0
A18: Totaal Rekening-courant aandeelhouder | C18: =SUM(C17) -> 110497 | D18: =SUM(D17) -> 0 | E18: =SUM(E17) -> 0 | F18: =SUM(C18:E18) -> 110497 | H18: =SUM(H17) -> 0
A20: 2040700 | B20: VOR Vooruitbetaalde servicekosten | C20: 0 | D20: 15594 | E20: 0 | F20: =SUM(C20:E20) -> 15594 | H20: 0
A21: 2040900 | B21: VOR Vooruitbetaalde overige kosten | C21: 0 | D21: 737 | E21: 0 | F21: =SUM(C21:E21) -> 737 | H21: 0
A22: Totaal overige vorderingen | C22: =SUM(C20:C21) -> 0 | D22: =SUM(D20:D21) -> 16331 | E22: =SUM(E20:E21) -> 0 | F22: =SUM(C22:E22) -> 16331 | H22: =SUM(H20:H21) -> 0
A24: 2300000 | B24: LM Kruisposten | C24: 0 | D24: 0 | E24: 3338 | F24: =SUM(C24:E24) -> 3338 | H24: 3338
A25: 2400200 | B25: LM ABN AMRO Bank Disposal NL58 ABNA 0818 9180 39 | C25: 2404971 | D25: -1418387 | E25: -256886 | F25: =SUM(C25:E25) -> 729698 | H25: 649658
A26: 2400201 | B26: LM ABN AMRO Bank Deposit NL57 ABNA 0541 6205 68 | C26: 17820 | D26: -8172 | E26: 3265 | F26: =SUM(C26:E26) -> 12913 | H26: 12154
A27: 2400202 | B27: LM ABN AMRO Bank General NL93 ABNA 0541 6132 27 | C27: 23180 | D27: 168612 | E27: 599999 | F27: =SUM(C27:E27) -> 791791 | H27: 785758
A28: 2400203 | B28: LM ABN AMRO Bank Maintres NL04 ABNA 0541 6188 06 | C28: 435121 | D28: 56414 | E28: 91777 | F28: =SUM(C28:E28) -> 583312 | H28: -62925
A29: 2400204 | B29: LM ABN AMRO Bank Rent NL46 ABNA 0541 6088 35 | C29: 249024 | D29: 166400 | E29: 247984 | F29: =SUM(C29:E29) -> 663408 | H29: -364896
A30: 2400205 | B30: LM ABN AMRO Bank SR EXP NL88 ABNA 0541 6205 92 | C30: 149397 | D30: 125774 | E30: -274333 | F30: =SUM(C30:E30) -> 838 | H30: -115700
A31: Totaal Liquide middelen | C31: =SUM(C24:C30) -> 3279513 | D31: =SUM(D24:D30) -> -909359 | E31: =SUM(E24:E30) -> 415144 | F31: =SUM(C31:E31) -> 2785298 | H31: =SUM(H24:H30) -> 907387
A33: 1000002 | B33: EV Normale aandelen Saldo | C33: -1 | D33: 0 | E33: 0 | F33: =SUM(C33:E33) -> -1 | H33: 0
A34: 1100000 | B34: EV Agioreserve Agio aandelen | C34: -19431219 | D34: 0 | E34: 0 | F34: =SUM(C34:E34) -> -19431219 | H34: 0
A35: 1160000 | B35: EV Overige reserve Reserve aandelen | C35: =9890198-1711717+1831580 -> 10010061 | E35: 0 | F35: =SUM(C35:E35) -> 10010061 | H35: 0
A36: 1160100 | B36: EV Overige reserve Dividenduitkeringen aandelen | C36: 7497104 | D36: =230000 -> 230000 | E36: 820500 | F36: =SUM(C36:E36) -> 8547604 | H36: 285500
A37: Totaal Eigen vermogen | C37: =SUM(C33:C36) -> -1924055 | D37: =SUM(D33:D36) -> 230000 | E37: =SUM(E33:E36) -> 820500 | F37: =SUM(C37:E37) -> -873555 | H37: =SUM(H33:H36) -> 285500
A39: 1930001 | B39: LLS Hoofdsom ABN AMRO Bank NV Senior Facility Agreement | C39: =-130000000 -> -130000000 | D39: 0 | E39: 0 | F39: =SUM(C39:E39) -> -130000000 | H39: 0
A40: 1930101 | B40: LLS Cum aflossingen ABN AMRO Bank NV Senior Facility Agreement | C40: 1625000 | D40: 3445233 | E40: 5294156 | F40: =SUM(C40:E40) -> 10364389 | H40: 601184
A41: 1930201 | B41: LLS Kortlopend deel ABN AMRO Bank NV Senior Facility Agreement | C41: 0 | D41: -306834 | E41: 306834 | F41: =SUM(C41:E41) -> 0 | H41: 0
A42: Totaal Langlopende schulden | C42: =SUM(C39:C41) -> -128375000 | D42: =SUM(D39:D41) -> 3138399 | E42: =SUM(E39:E41) -> 5600990 | F42: =SUM(C42:E42) -> -119635611 | H42: =SUM(H39:H41) -> 601184
A44: 2730000 | B44: KLS Crediteuren | C44: 0 | D44: -176869 | E44: 3388 | F44: =SUM(C44:E44) -> -173481 | H44: 28193
A45: 2730001 | B45: KLS Crediteuren intercompany | C45: 0 | D45: 0 | E45: 0 | F45: =SUM(C45:E45) -> 0 | H45: 0
A46: Totaal Crediteuren | C46: =SUM(C44:C45) -> 0 | D46: =SUM(D44:D45) -> -176869 | E46: =SUM(E44:E45) -> 3388 | F46: =SUM(C46:E46) -> -173481 | H46: =SUM(H44:H45) -> 28193
A48: 2512100 | B48: BEL Afgedragen/ontvangen BTW | C48: -6835 | D48: -1031 | E48: 4140 | F48: =SUM(C48:E48) -> -3726 | H48: -19
A49: 2530000 | B49: BEL Te betalen vennootschapsbelasting | C49: -331450 | D49: 165522 | E49: -272134 | F49: =SUM(C49:E49) -> -438062 | H49: -74792
A50: 2550000 | B50: BEL Te betalen overige belastingen | C50: 0 | D50: -1045 | E50: 95924 | F50: =SUM(C50:E50) -> 94879 | H50: -94878
...

Sheet BDO Q4 2019
C1: Eindbalans 31-12-2018 | D1: Mutaties periode Q1 2019 | E1: Mutaties Q2 2019 | F1: Mutaties Q3 2019 | G1: Mutaties Q4 2019 | H1: Saldi per 31-12-2019
A3: Balans
A4: 1600200 | B4: VG Vastgoedbeleggingen Verkrijgings- of vervaardigingsprijs | C4: =134929585-2259117 -> 132670468 | F4: 0 | H4: =SUM(C4:G4) -> 132670468
A5: 1600200 | B5: VG Vastgoedbeleggingen Cum afschrijvingen en waardeverm | C5: =-8074670+120270 -> -7954400 | D5: -662362 | E5: -650161 | F5: -653662 | G5: -656408 | H5: =SUM(C5:G5) -> -10576993
A6: 1610803 | B6: VG Comm VG in exploitatie Buitengebruikstellingen aanschaffingswaarde | D6: -651550 | E6: -1101554 | F6: -462286 | G6: -1443087 | H6: =SUM(C6:G6) -> -3658477
A7: 1611003 | B7: VG Comm VG in exploitatie Buitengebruikstellingen cum. afschr. en waardeverm. | D7: 41286 | E7: 71536 | F7: 33933 | G7: 116170 | H7: =SUM(C7:G7) -> 262925
A8: Totaal Vastgoedbeleggingen
A10: 1790002 | B10: FVA Latente belastingvordering langlopend | C10: 2396007 | D10: 168662 | E10: 142232 | F10: 153794 | G10: 129418 | H10: =SUM(C10:G10) -> 2990113
A11: Totaal Financiële vaste activa
A13: 2000000 | B13: VOR Debiteuren | C13: 119205 | D13: 158343 | E13: 66045 | F13: -93669 | G13: -177050 | H13: =SUM(C13:G13) -> 72874
A14: 2000300 | B14: VOR Voorziening dubieuze debiteuren | C14: -64501 | D14: 0 | E14: 0 | F14: 0 | G14: 0 | H14: =SUM(C14:G14) -> -64501
A15: Totaal Debiteuren
A17: 2640000 | B17: RC Kortlopend DMRRP INV - I BV | C17: 110497 | D17: 0 | E17: 0 | F17: 0 | G17: 0 | H17: =SUM(C17:G17) -> 110497
A18: Totaal Rekening-courant aandeelhouder
A20: 2040200 | B20: VOR Te vorderen waarborgsommen kortlopen | C20: 0 | D20: 0 | E20: 0 | F20: 0 | G20: 5000 | H20: =SUM(C20:G20) -> 5000
A21: 2040700 | B21: VOR Vooruitbetaalde servicekosten | C21: 15594 | D21: 0 | E21: 0 | F21: 0 | G21: -15581 | H21: =SUM(C21:G21) -> 13
A22: 2040900 | B22: VOR Vooruitbetaalde overige kosten | C22: 737 | D22: 0 | E22: 0 | F22: 0 | G22: 0 | H22: =SUM(C22:G22) -> 737
A23: Totaal overige vorderingen
A25: 2300000 | B25: LM Kruisposten | C25: 0 | D25: 672 | E25: -672 | F25: 3338 | G25: 547 | H25: =SUM(C25:G25) -> 3885
A26: 2400200 | B26: LM ABN AMRO Bank Disposal NL58 ABNA 0818 9180 39 | C26: 986584 | D26: -447623 | E26: -458920 | F26: 649658 | G26: 1729271 | H26: =SUM(C26:G26)-2 -> 2458968
A27: 2400201 | B27: LM ABN AMRO Bank Deposit NL57 ABNA 0541 6205 68 | C27: 9648 | D27: 1359967 | E27: -1368856 | F27: 12154 | G27: 74896 | H27: =SUM(C27:G27) -> 87809
A28: 2400202 | B28: LM ABN AMRO Bank General NL93 ABNA 0541 6132 27 | C28: 191790 | D28: 842838 | E28: -1028597 | F28: 785758 | G28: -19584 | H28: =SUM(C28:G28)+2 -> 772207
A29: 2400203 | B29: LM ABN AMRO Bank Maintres NL04 ABNA 0541 6188 06 | C29: 491534 | D29: 109815 | E29: 44887 | F29: -62925 | G29: 66151 | H29: =SUM(C29:G29) -> 649462
A30: 2400204 | B30: LM ABN AMRO Bank Rent NL46 ABNA 0541 6088 35 | C30: 415425 | D30: 84312 | E30: 528567 | F30: -364896 | G30: 1098220 | H30: =SUM(C30:G30) -> 1761628
A31: 2400205 | B31: LM ABN AMRO Bank SR EXP NL88 ABNA 0541 6205 92 | C31: 275171 | D31: -217031 | E31: 58399 | F31: -115700 | G31: 194761 | H31: =SUM(C31:G31) -> 195600
A32: Totaal Liquide middelen
A34: 1000002 | B34: EV Normale aandelen Saldo | C34: -1 | D34: 0 | E34: 0 | F34: 0 | G34: 0 | H34: =SUM(C34:G34) -> -1
A35: 1100000 | B35: EV Agioreserve Agio aandelen | C35: -19431219 | D35: 0 | E35: 0 | F35: 0 | G35: 0 | H35: =SUM(C35:G35) -> -19431219
A36: 1160000 | B36: EV Overige reserve Reserve aandelen | C36: =9890198-1340715+7727104 -> 16276587 | D36: 0 | E36: 0 | F36: 0 | G36: 0 | H36: =SUM(C36:G36) -> 16276587
A37: 1160100 | B37: EV Overige reserve Dividenduitkeringen aandelen | C37: 0 | D37: 310000 | E37: 225000 | F37: 285500 | G37: 235000 | H37: =SUM(C37:G37) -> 1055500
A38: Totaal Eigen vermogen
H39: =SUM(C39:G39) -> 0
A40: 1930001 | B40: LLS Hoofdsom ABN AMRO Bank NV Senior Facility Agreement | C40: -130000000 | D40: 0 | E40: 0 | F40: 0 | G40: 0 | H40: =SUM(C40:G40) -> -130000000
A41: 1930101 | B41: LLS Cum aflossingen ABN AMRO Bank NV Senior Facility Agreement | C41: 5070233 | D41: 0 | E41: 4692972 | F41: 601184 | G41: 601184 | H41: =SUM(C41:G41) -> 10965573
A42: 1930201 | B42: LLS Kortlopend deel ABN AMRO Bank NV Senior Facility Agreement | C42: -306834 | D42: 306834 | E42: 0 | F42: 0 | G42: 0 | H42: =SUM(C42:G42) -> 0
A43: Totaal Langlopende schulden
A45: 2730000 | B45: KLS Crediteuren | C45: -176869 | D45: -18824 | E45: -5981 | F45: 28193 | G45: -55987 | H45: =SUM(C45:G45) -> -229468
A46: 2730001 | B46: KLS Crediteuren intercompany | C46: 0 | D46: 0 | E46: 0 | F46: 0 | G46: 0 | H46: =SUM(C46:G46) -> 0
A47: Totaal Crediteuren
H48: =SUM(C48:G48) -> 0
...

Sheet BDO - Q1 2020
C1: Eindbalans 31-03-2019 | D1: Mutaties Q2 2019 | E1: Mutaties Q3 2019 | F1: Mutaties Q4 2019 | G1: Mutaties Q1 2020 | H1: Saldi per 31-03-2020
A3: Balans
A4: 1600200 | B4: VG Vastgoedbeleggingen Verkrijgings- of vervaardigingsprijs | C4: 132670468 | E4: 0 | G4: -3658477 | H4: =SUM(C4:G4) -> 129011991
A5: 1600200 | B5: VG Vastgoedbeleggingen Cum afschrijvingen en waardeverm | C5: -8616762 | D5: -650161 | E5: -653662 | F5: -656408 | G5: -380013 | H5: =SUM(C5:G5) -> -10957006
A6: 1610803 | B6: VG Comm VG in exploitatie Buitengebruikstellingen aanschaffingswaarde | C6: -651550 | D6: -1101554 | E6: -462286 | F6: -1443087 | G6: 2472387 | H6: =SUM(C6:G6) -> -1186090
A7: 1611003 | B7: VG Comm VG in exploitatie Buitengebruikstellingen cum. afschr. en waardeverm. | C7: 41286 | D7: 71536 | E7: 33933 | F7: 116170 | G7: -162402 | H7: =SUM(C7:G7) -> 100523
A8: Totaal Vastgoedbeleggingen
A10: 1790002 | B10: FVA Latente belastingvordering langlopend | C10: 2564669 | D10: 142232 | E10: 153794 | F10: 129418 | G10: -293081 | H10: =SUM(C10:G10) -> 2697032
A11: Totaal Financiële vaste activa
A13: 2000000 | B13: VOR Debiteuren | C13: 277548 | D13: 66045 | E13: -93669 | F13: -177050 | G13: 5313 | H13: =SUM(C13:G13) -> 78187
A14: 2000300 | B14: VOR Voorziening dubieuze debiteuren | C14: -64501 | D14: 0 | E14: 0 | F14: 0 | G14: 0 | H14: =SUM(C14:G14) -> -64501
A15: Totaal Debiteuren
A17: 2640000 | B17: RC Kortlopend DMRRP INV - I BV | C17: 110497 | D17: 0 | E17: 0 | F17: 0 | G17: 100000 | H17: =SUM(C17:G17) -> 210497
A18: Totaal Rekening-courant aandeelhouder
A20: 2040200 | B20: VOR Te vorderen waarborgsommen kortlopen | C20: 0 | D20: 0 | E20: 0 | F20: 5000 | G20: 0 | H20: =SUM(C20:G20) -> 5000
A21: 2040700 | B21: VOR Vooruitbetaalde servicekosten | C21: 15594 | D21: 0 | E21: 0 | F21: -10713 | G21: 0 | H21: =SUM(C21:G21) -> 4881
A22: 2040900 | B22: VOR Vooruitbetaalde overige kosten | D22: 0 | E22: 0 | F22: 425 | G22: 0 | H22: =SUM(C22:G22) -> 425
A23: Totaal overige vorderingen
A25: 2300000 | B25: LM Kruisposten | C25: 672 | D25: -4010 | E25: 3338 | F25: 0 | H25: =SUM(C25:G25) -> 0
A26: 2400200 | B26: LM ABN AMRO Bank Disposal NL58 ABNA 0818 9180 39 | C26: 538961 | D26: -458920 | E26: 649658 | F26: 1729271 | G26: -1031638 | H26: =SUM(C26:G26) -> 1427332
A27: 2400201 | B27: LM ABN AMRO Bank Deposit NL57 ABNA 0541 6205 68 | C27: 1369615 | D27: -1368856 | E27: 12154 | F27: 74896 | G27: 1058693 | H27: =SUM(C27:G27) -> 1146502
A28: 2400202 | B28: LM ABN AMRO Bank General NL93 ABNA 0541 6132 27 | C28: 1034628 | D28: -1028597 | E28: 785758 | F28: -19584 | G28: -29065 | H28: =SUM(C28:G28) -> 743140
A29: 2400203 | B29: LM ABN AMRO Bank Maintres NL04 ABNA 0541 6188 06 | C29: 601349 | D29: 44887 | E29: -62925 | F29: 66151 | G29: -46640 | H29: =SUM(C29:G29) -> 602822
A30: 2400204 | B30: LM ABN AMRO Bank Rent NL46 ABNA 0541 6088 35 | C30: 499737 | D30: 528567 | E30: -364896 | F30: 1098220 | G30: -73423 | H30: =SUM(C30:G30) -> 1688205
A31: 2400205 | B31: LM ABN AMRO Bank SR EXP NL88 ABNA 0541 6205 92 | C31: 58140 | D31: 58399 | E31: -115700 | F31: 194761 | G31: 114437 | H31: =SUM(C31:G31) -> 310037
A32: Totaal Liquide middelen
A34: 1000002 | B34: EV Normale aandelen Saldo | C34: -1 | D34: 0 | E34: 0 | F34: 0 | G34: 0 | H34: =SUM(C34:G34) -> -1
A35: 1100000 | B35: EV Agioreserve Agio aandelen | C35: -19431219 | D35: 0 | E35: 0 | F35: 0 | G35: 0 | H35: =SUM(C35:G35) -> -19431219
A36: 1160000 | B36: EV Overige reserve Reserve aandelen | C36: =16276587-1251333-650 -> 15024604 | D36: 0 | E36: 0 | F36: 0 | G36: 0 | H36: =SUM(C36:G36) -> 15024604
A37: 1160100 | B37: EV Overige reserve Dividenduitkeringen aandelen | C37: 310000 | D37: 225000 | E37: 285500 | F37: 235000 | G37: 1510938 | H37: =SUM(C37:G37) -> 2566438
A38: Totaal Eigen vermogen
A40: 1930001 | B40: LLS Hoofdsom ABN AMRO Bank NV Senior Facility Agreement | C40: -130000000 | D40: 0 | E40: 0 | F40: 0 | G40: 0 | H40: =SUM(C40:G40) -> -130000000
A41: 1930101 | B41: LLS Cum aflossingen ABN AMRO Bank NV Senior Facility Agreement | C41: 5070233 | D41: 4692972 | E41: 601184 | F41: 601184 | G41: 2258971 | H41: =SUM(C41:G41) -> 13224544
A42: 1930201 | B42: LLS Kortlopend deel ABN AMRO Bank NV Senior Facility Agreement | C42: 0 | D42: 0 | E42: 0 | F42: 0 | G42: 0 | H42: =SUM(C42:G42) -> 0
A43: Totaal Langlopende schulden
A45: 2730000 | B45: KLS Crediteuren | C45: -195693 | D45: -5981 | E45: 28193 | F45: -67126 | G45: 17250 | H45: =SUM(C45:G45) -> -223357
A46: 2730001 | B46: KLS Crediteuren intercompany | C46: 0 | D46: 0 | E46: 0 | F46: 0 | G46: 0 | H46: =SUM(C46:G46) -> 0
A47: Totaal Crediteuren
H48: =SUM(C48:F48) -> 0
A49: 2512100 | B49: BEL Afgedragen/ontvangen BTW | C49: -3716 | D49: 9 | E49: -19 | F49: -204 | G49: 17 | H49: =SUM(C49:G49) -> -3913
...

Sheet BDO - Q2 2020
C1: Eindbalans 30-06-2019 | D1: Mutaties Q3 2019 | E1: Mutaties Q4 2019 | F1: Mutaties Q1 2020 | G1: Mutaties Q2 2020 | H1: Saldi per 30-06-2020
C2: =$C$4+SUM(C5:C7) -> 121763263 | D2: =$C$4+SUM($C$5:D7) -> 120681248 | E2: =$C$4+SUM($C$5:E7) -> 118697923 | F2: =$C$4+SUM($C$5:F7)+F4 -> 116969418 | G2: =$C$4+SUM($C$5:G7)+F4 -> 115573453
A3: Balans
A4: 1600200 | B4: VG Vastgoedbeleggingen Verkrijgings- of vervaardigingsprijs | C4: 132670468 | D4: 0 | F4: -3658477 | H4: =SUM(C4:G4) -> 129011991
A5: 1600200 | B5: VG Vastgoedbeleggingen Cum afschrijvingen en waardeverm | C5: -9266923 | D5: -653662 | E5: -656408 | F5: -380013 | G5: -630199 | H5: =SUM(C5:G5) -> -11587205 | J5: 540977
A6: 1610803 | B6: VG Comm VG in exploitatie Buitengebruikstellingen aanschaffingswaarde | C6: -1753104 | D6: -462286 | E6: -1443087 | F6: 2472387 | G6: -841866 | H6: =SUM(C6:G6) -> -2027956
A7: 1611003 | B7: VG Comm VG in exploitatie Buitengebruikstellingen cum. afschr. en waardeverm. | C7: 112822 | D7: 33933 | E7: 116170 | F7: -162402 | G7: 76100 | H7: =SUM(C7:G7) -> 176623
A8: Totaal Vastgoedbeleggingen | C8: 0
C9: 0
A10: 1790002 | B10: FVA Latente belastingvordering langlopend | C10: 2706901 | D10: 153794 | E10: -278091 | F10: -293081 | G10: 524916 | H10: =SUM(C10:G10) -> 2814439
A11: Totaal Financiële vaste activa | C11: 0
C12: 0
A13: 2000000 | B13: VOR Debiteuren | C13: 343593 | D13: -93669 | E13: -177050 | F13: 220477 | G13: -208231 | H13: =SUM(C13:G13) -> 85120
A14: 2000300 | B14: VOR Voorziening dubieuze debiteuren | C14: -64501 | D14: 0 | E14: 8960 | F14: 0 | H14: =SUM(C14:G14) -> -55541
A15: Totaal Debiteuren | C15: 0
C16: 0
A17: 2640000 | B17: RC Kortlopend DMRRP INV - I BV | C17: 110497 | D17: 0 | E17: -2023897 | H17: =SUM(C17:G17) -> -1913400
A18: Totaal Rekening-courant aandeelhouder | C18: 0
C19: 0
A20: 2040200 | B20: VOR Te vorderen waarborgsommen kortlopen | C20: 0 | D20: 0 | E20: 5000 | F20: 0 | H20: =SUM(C20:G20) -> 5000
A21: 2040700 | B21: VOR Vooruitbetaalde servicekosten | C21: 15594 | D21: 0 | E21: -11776 | F21: 0 | H21: =SUM(C21:G21) -> 3818
A22: 2040900 | B22: VOR Vooruitbetaalde overige kosten | C22: 0 | D22: 0 | E22: 425 | F22: 0 | G22: =I88+I90+I91+I105+I113 -> 407396 | H22: =SUM(C22:G22) -> 407821
A23: Totaal overige vorderingen | C23: 0
C24: 0
A25: 2300000 | B25: LM Kruisposten | C25: -3338 | D25: 3338 | E25: 0 | G25: 0 | H25: =SUM(C25:G25) -> 0
A26: 2400200 | B26: LM ABN AMRO Bank Disposal NL58 ABNA 0818 9180 39 | C26: 80041 | D26: 649658 | E26: 1729271 | F26: -1031638 | G26: -1408139 | H26: =SUM(C26:G26) -> 19193
A27: 2400201 | B27: LM ABN AMRO Bank Deposit NL57 ABNA 0541 6205 68 | C27: 759 | D27: 12154 | E27: 74896 | F27: 1058693 | G27: -1109732 | H27: =SUM(C27:G27) -> 36770
A28: 2400202 | B28: LM ABN AMRO Bank General NL93 ABNA 0541 6132 27 | C28: 6031 | D28: 785758 | E28: -19584 | F28: -29065 | G28: -50664 | H28: =SUM(C28:G28) -> 692476
A29: 2400203 | B29: LM ABN AMRO Bank Maintres NL04 ABNA 0541 6188 06 | C29: 646236 | D29: -62925 | E29: 66151 | F29: -46640 | G29: -159674 | H29: =SUM(C29:G29) -> 443148
A30: 2400204 | B30: LM ABN AMRO Bank Rent NL46 ABNA 0541 6088 35 | C30: 1028304 | D30: -364896 | E30: 1098220 | F30: -73423 | G30: -420964 | H30: =SUM(C30:G30) -> 1267241
A31: 2400205 | B31: LM ABN AMRO Bank SR EXP NL88 ABNA 0541 6205 92 | C31: 116539 | D31: -115700 | E31: 194761 | F31: 114437 | G31: -265290 | H31: =SUM(C31:G31) -> 44747
A32: Totaal Liquide middelen | C32: 0
C33: 0
A34: 1000002 | B34: EV Normale aandelen Saldo | C34: -1 | D34: 0 | E34: 0 | F34: 0 | H34: =SUM(C34:G34) -> -1
A35: 1100000 | B35: EV Agioreserve Agio aandelen | C35: -19431219 | D35: 0 | E35: 0 | F35: 100000 | H35: =SUM(C35:G35) -> -19331219
A36: 1160000 | B36: EV Overige reserve Reserve aandelen | C36: 13633366 | D36: 0 | E36: 0 | F36: 0 | H36: =SUM(C36:G36) -> 13633366
A37: 1160100 | B37: EV Overige reserve Dividenduitkeringen aandelen | C37: 535000 | D37: 285500 | E37: 235000 | F37: 1510938 | G37: 1397717 | H37: =SUM(C37:G37) -> 3964155
A38: Totaal Eigen vermogen | C38: 0
C39: 0
A40: 1930001 | B40: LLS Hoofdsom ABN AMRO Bank NV Senior Facility Agreement | C40: -130000000 | D40: 0 | E40: 0 | F40: 0 | H40: =SUM(C40:G40) -> -130000000
...

Sheet BDO - Q3 2020
C1: Eindbalans 30-09-2019 | D1: Mutaties Q4 2019 | E1: Mutaties Q1 2020 | F1: Mutaties Q2 2020 | G1: Mutaties Q3 | H1: Saldi per 30-09-2020
A3: Balans
A4: 1600200 | B4: VG Vastgoedbeleggingen Verkrijgings- of vervaardigingsprijs | C4: 132670468 | E4: -3658477 | F4: 153567 | H4: =SUM(C4:G4) -> 129165558 | I4: V
A5: 1600200 | B5: VG Vastgoedbeleggingen Cum afschrijvingen en waardeverm | C5: -9920585 | D5: -656408 | E5: -380013 | F5: =-630199 -> -630199 | G5: -653151 | H5: =SUM(C5:G5) -> -12240356 | I5: V
A6: 1610803 | B6: VG Comm VG in exploitatie Buitengebruikstellingen aanschaffingswaarde | C6: -2215390 | D6: -1443087 | E6: 2472387 | F6: -841866 | G6: -947310 | H6: =SUM(C6:G6) -> -2975266 | I6: V
A7: 1611003 | B7: VG Comm VG in exploitatie Buitengebruikstellingen cum. afschr. en waardeverm. | C7: 146755 | D7: 116170 | E7: -162402 | F7: 76100 | G7: 90299 | H7: =SUM(C7:G7) -> 266922 | I7: V
A8: Totaal Vastgoedbeleggingen | C8: 0
C9: 0
A10: 1790002 | B10: FVA Latente belastingvordering langlopend | C10: 2860695 | D10: -278091 | E10: -293081 | F10: 524916 | G10: 118583 | H10: =SUM(C10:G10) -> 2933022 | I10: V
A11: Totaal Financiële vaste activa | C11: 0
C12: 0
A13: 2000000 | B13: VOR Debiteuren | C13: 249924 | D13: -177050 | E13: 220477 | F13: -208231 | G13: 316526 | H13: =SUM(C13:G13) -> 401646 | I13: V
A14: 2000300 | B14: VOR Voorziening dubieuze debiteuren | C14: -64501 | D14: 8960 | E14: 0 | H14: =SUM(C14:F14) -> -55541 | I14: V
A15: Totaal Debiteuren | C15: 0
C16: 0
A17: 2640000 | B17: RC Kortlopend DMRRP INV - I BV | C17: 110497 | D17: -2023897 | G17: 1642583 | H17: =SUM(C17:G17) -> -270817 | I17: V
A18: Totaal Rekening-courant aandeelhouder | C18: 0
C19: 0
A20: 2040200 | B20: VOR Te vorderen waarborgsommen kortlopen | C20: 0 | D20: 5000 | E20: 0 | H20: =SUM(C20:F20) -> 5000 | I20: V
A21: 2040700 | B21: VOR Vooruitbetaalde servicekosten | C21: 15594 | D21: -11776 | E21: 0 | H21: =SUM(C21:F21) -> 3818 | I21: V
A22: 2040900 | B22: VOR Vooruitbetaalde overige kosten | C22: 0 | D22: 425 | E22: -65069 | F22: 360152 | G22: -139615 | H22: =SUM(C22:G22) -> 155893 | I22: V
A23: Totaal overige vorderingen | C23: 0
C24: 0
A25: 2300000 | B25: LM Kruisposten | C25: 0 | D25: 0 | F25: 0 | H25: =SUM(C25:F25) -> 0
A26: 2400200 | B26: LM ABN AMRO Bank Disposal NL58 ABNA 0818 9180 39 | C26: 729699 | D26: 1729271 | E26: -1031638 | F26: -1408139 | G26: -18700 | H26: =SUM(C26:G26) -> 493
A27: 2400201 | B27: LM ABN AMRO Bank Deposit NL57 ABNA 0541 6205 68 | C27: 12913 | D27: 74896 | E27: 1058693 | F27: -1109732 | G27: -19 | H27: =SUM(C27:G27) -> 36751
A28: 2400202 | B28: LM ABN AMRO Bank General NL93 ABNA 0541 6132 27 | C28: 791789 | D28: -19584 | E28: -29065 | F28: -50664 | G28: -417400 | H28: =SUM(C28:G28) -> 275076
A29: 2400203 | B29: LM ABN AMRO Bank Maintres NL04 ABNA 0541 6188 06 | C29: 583311 | D29: 66151 | E29: -46640 | F29: -159674 | G29: 145814 | H29: =SUM(C29:G29) -> 588962
A30: 2400204 | B30: LM ABN AMRO Bank Rent NL46 ABNA 0541 6088 35 | C30: 663408 | D30: 1098220 | E30: -73423 | F30: -420964 | G30: -850699 | H30: =SUM(C30:G30) -> 416542
A31: 2400205 | B31: LM ABN AMRO Bank SR EXP NL88 ABNA 0541 6205 92 | C31: 839 | D31: 194761 | E31: 114437 | F31: -265290 | G31: 133175 | H31: =SUM(C31:G31) -> 177922
A32: Totaal Liquide middelen | C32: 0
C33: 0
A34: 1000002 | B34: EV Normale aandelen Saldo | C34: -1 | D34: 0 | E34: 0 | H34: =SUM(C34:F34) -> -1 | I34: V
A35: 1100000 | B35: EV Agioreserve Agio aandelen | C35: -19431219 | D35: 0 | E35: 100000 | H35: =SUM(C35:F35) -> -19331219 | I35: V
A36: 1160000 | B36: EV Overige reserve Reserve aandelen | C36: 12988943 | D36: 0 | E36: 0 | H36: =SUM(C36:F36) -> 12988943 | I36: V
A37: 1160100 | B37: EV Overige reserve Dividenduitkeringen aandelen | C37: 820500 | D37: 235000 | E37: 1510938 | F37: 1397717 | G37: 207000 | H37: =SUM(C37:G37) -> 4171155 | I37: V
A38: Totaal Eigen vermogen | C38: 0
C39: 0
A40: 1930001 | B40: LLS Hoofdsom ABN AMRO Bank NV Senior Facility Agreement | C40: -130000000 | D40: 0 | E40: 0 | H40: =SUM(C40:F40) -> -130000000 | I40: V
A41: 1930101 | B41: LLS Cum aflossingen ABN AMRO Bank NV Senior Facility Agreement | C41: 10364389 | D41: 601184 | E41: 2258971 | F41: 3569138 | G41: 1387184 | H41: =SUM(C41:G41) -> 18180866 | I41: V
...

Sheet BDO - Q4 2020
C1: Eindbalans 31-12-2019 | D1: Mutaties Q1 2020 | E1: Mutaties Q2 2020 | F1: Mutaties Q3 | G1: Mutaties Q4 | H1: Saldi per 31-12-2020
A3: Balans
A4: 1600200 | B4: VG Vastgoedbeleggingen Verkrijgings- of vervaardigingsprijs | C4: 133211445 | D4: -3658477 | E4: 153567 | G4: 74328 | H4: =SUM(C4:G4) -> 129780863
A5: 1600200 | B5: VG Vastgoedbeleggingen Cum afschrijvingen en waardeverm | C5: -10576993 | D5: -380013 | E5: =-630199 -> -630199 | F5: -653151 | G5: -654632 | H5: =SUM(C5:G5) -> -12894988
A6: 1610803 | B6: VG Comm VG in exploitatie Buitengebruikstellingen aanschaffingswaarde | C6: -3658477 | D6: 2472387 | E6: -841866 | F6: -947310 | G6: -1073484 | H6: =SUM(C6:G6) -> -4048750
A7: 1611003 | B7: VG Comm VG in exploitatie Buitengebruikstellingen cum. afschr. en waardeverm. | C7: 262925 | D7: -162402 | E7: 76100 | F7: 90299 | G7: 110448 | H7: =SUM(C7:G7) -> 377370
A8: Totaal Vastgoedbeleggingen
A10: 1790002 | B10: FVA Latente belastingvordering langlopend | C10: 2582604 | D10: -293081 | E10: 524916 | F10: 118583 | G10: 576960 | H10: =SUM(C10:G10) -> 3509982
A11: Totaal Financiële vaste activa
A13: 2000000 | B13: VOR Debiteuren | C13: 72874 | D13: 220477 | E13: -208231 | F13: 316526 | G13: -108369 | H13: =SUM(C13:G13) -> 293277
A14: 2000300 | B14: VOR Voorziening dubieuze debiteuren | C14: -55541 | D14: 0 | G14: 0 | H14: =SUM(C14:G14) -> -55541
A15: Totaal Debiteuren
A17: 2640000 | B17: RC Kortlopend DMRRP INV - I BV | C17: -1913400 | F17: 1642583 | G17: 1116604 | H17: =SUM(C17:G17) -> 845787
A18: Totaal Rekening-courant aandeelhouder
A20: 2040200 | B20: VOR Te vorderen waarborgsommen kortlopen | C20: 5000 | D20: 0 | H20: =SUM(C20:G20) -> 5000
A21: 2040700 | B21: VOR Vooruitbetaalde servicekosten | C21: 3818 | D21: 0 | H21: =SUM(C21:G21) -> 3818
A22: 2040900 | B22: VOR Vooruitbetaalde overige kosten | C22: 425 | D22: -65069 | E22: 360152 | F22: -139615 | G22: -155468 | H22: =SUM(C22:G22) -> 425
A23: Totaal overige vorderingen
A25: 2300000 | B25: LM Kruisposten | C25: 0 | E25: 0 | H25: =SUM(C25:G25) -> 0
A26: 2400200 | B26: LM ABN AMRO Bank Disposal NL58 ABNA 0818 9180 39 | C26: 2458970 | D26: -1031638 | E26: -1408139 | F26: -18700 | G26: -482 | H26: =SUM(C26:G26) -> 11
A27: 2400201 | B27: LM ABN AMRO Bank Deposit NL57 ABNA 0541 6205 68 | C27: 87809 | D27: 1058693 | E27: -1109732 | F27: -19 | G27: -19 | H27: =SUM(C27:G27) -> 36732
A28: 2400202 | B28: LM ABN AMRO Bank General NL93 ABNA 0541 6132 27 | C28: 772205 | D28: -29065 | E28: -50664 | F28: -417400 | G28: -13600 | H28: =SUM(C28:G28) -> 261476
A29: 2400203 | B29: LM ABN AMRO Bank Maintres NL04 ABNA 0541 6188 06 | C29: 649462 | D29: -46640 | E29: -159674 | F29: 145814 | G29: -495089 | H29: =SUM(C29:G29) -> 93873
A30: 2400204 | B30: LM ABN AMRO Bank Rent NL46 ABNA 0541 6088 35 | C30: 1761630 | D30: -73423 | E30: -420964 | F30: -850699 | G30: 550068 | H30: =SUM(C30:G30) -> 966612
A31: 2400205 | B31: LM ABN AMRO Bank SR EXP NL88 ABNA 0541 6205 92 | C31: 195600 | D31: 114437 | E31: -265290 | F31: 133175 | G31: -24647 | H31: =SUM(C31:G31) -> 153275
A32: Totaal Liquide middelen
A34: 1000002 | B34: EV Normale aandelen Saldo | C34: -1 | D34: 0 | G34: 0 | H34: =SUM(C34:G34) -> -1
A35: 1100000 | B35: EV Agioreserve Agio aandelen | C35: -19431219 | D35: 100000 | G35: 0 | H35: =SUM(C35:G35) -> -19331219
A36: 1160000 | B36: EV Overige reserve Reserve aandelen | C36: 12717900 | D36: 0 | G36: 0 | H36: =SUM(C36:G36) -> 12717900
A37: 1160100 | B37: EV Overige reserve Dividenduitkeringen aandelen | C37: 1055500 | D37: 1510938 | E37: 1397717 | F37: 207000 | G37: 0 | H37: =SUM(C37:G37) -> 4171155
A38: Totaal Eigen vermogen
A40: 1930001 | B40: LLS Hoofdsom ABN AMRO Bank NV Senior Facility Agreement | C40: -130000000 | D40: 0 | E40: 0 | F40: 0 | G40: 0 | H40: =SUM(C40:G40) -> -130000000
A41: 1930101 | B41: LLS Cum aflossingen ABN AMRO Bank NV Senior Facility Agreement | C41: 10965573 | D41: 2258971 | E41: 3569138 | F41: 1387184 | G41: 1984184 | H41: =SUM(C41:G41) -> 20165050
A42: Totaal Langlopende schulden
A44: 2730000 | B44: KLS Crediteuren | C44: -229468 | D44: 17250 | E44: 900 | F44: -11928 | G44: 0 | H44: =SUM(C44:G44) -> -223246
A45: 2730001 | B45: KLS Crediteuren intercompany | C45: 0 | D45: 0 | E45: 0 | F45: 0 | G45: 0 | H45: =SUM(C45:G45) -> 0
A46: Totaal Crediteuren
A48: 2512100 | B48: BEL Afgedragen/ontvangen BTW | C48: -3930 | D48: 17 | E48: 271 | F48: -22 | G48: 2114 | H48: =SUM(C48:G48) -> -1550
A49: 2530000 | B49: BEL Te betalen vennootschapsbelasting | C49: 0 | D49: 0 | E49: 0 | F49: 0 | G49: 0 | H49: =SUM(C49:G49) -> 0
A50: 2550000 | B50: BEL Te betalen overige belastingen | C50: 0 | D50: 0 | E50: 0 | F50: 0 | G50: 0 | H50: =SUM(C50:G50) -> 0
...

Sheet BDO - Q1 2021
C1: Eindbalans 31-01-2020 | D1: Mutaties Q2 2020 | E1: Mutaties Q3 2020 | F1: Mutaties Q4 2020 | G1: Mutaties Q1 2021 | H1: Saldi per 31-03-2021
A3: Balans | J3: 449927 | K3: Q4
A4: 1600200 | B4: VG Vastgoedbeleggingen Verkrijgings- of vervaardigingsprijs | C4: 129552968 | D4: 153567 | H4: =SUM(C4:G4) -> 129706535 | J4: 172507 | K4: Q3
A5: 1600200 | B5: VG Vastgoedbeleggingen Cum afschrijvingen en waardeverm | C5: -10957006 | D5: =-630199 -> -630199 | E5: -653151 | F5: -654632 | G5: -277132 | H5: =SUM(C5:G5) -> -13172120
A6: 1610803 | B6: VG Comm VG in exploitatie Buitengebruikstellingen aanschaffingswaarde | C6: -1186090 | D6: -841866 | E6: -947310 | F6: -1073484 | G6: -706761 | H6: =SUM(C6:G6) -> -4755511
A7: 1611003 | B7: VG Comm VG in exploitatie Buitengebruikstellingen cum. afschr. en waardeverm. | C7: 100523 | D7: 76100 | E7: 90299 | F7: 110448 | G7: -303581 | H7: =SUM(C7:G7) -> 73789
A8: Totaal Vastgoedbeleggingen
A10: 1790002 | B10: FVA Latente belastingvordering langlopend | C10: 2289523 | D10: 524916 | E10: 118583 | F10: 576960 | G10: 142740 | H10: =SUM(C10:G10) -> 3652722
A11: Totaal Financiële vaste activa
A13: 2000000 | B13: VOR Debiteuren | C13: 293351 | D13: -208231 | E13: 316526 | F13: -108371 | G13: -341343 | H13: =SUM(C13:G13) -> -48068
A14: 2000300 | B14: VOR Voorziening dubieuze debiteuren | C14: -55541 | F14: 0 | G14: 0 | H14: =SUM(C14:G14) -> -55541
A15: Totaal Debiteuren | J15: =SUM(H4:H31) -> 119283553
J16: =SUM('Management Cijfers - Q2 2025'!AA3:AA9)+'Management Cijfers - Q2 2025'!AA11 -> 1.4800904e+08
A17: 2640000 | B17: RC Kortlopend DMRRP INV - I BV | C17: -1913400 | E17: 1642583 | F17: 1046231 | G17: 436656 | H17: =SUM(C17:G17) -> 1212070 | J17: =J16-J15 -> 28725487
A18: Totaal Rekening-courant aandeelhouder
A20: 2040200 | B20: VOR Te vorderen waarborgsommen kortlopen | C20: 5000 | H20: =SUM(C20:G20) -> 5000
A21: 2040700 | B21: VOR Vooruitbetaalde servicekosten | C21: 3818 | F21: -1022 | G21: -2796 | H21: =SUM(C21:G21) -> 0
A22: 2040900 | B22: VOR Vooruitbetaalde overige kosten | C22: -64644 | D22: 360152 | E22: -139615 | F22: -155413 | G22: 342768 | H22: =SUM(C22:G22) -> 343248
A23: Totaal overige vorderingen
A25: 2300000 | B25: LM Kruisposten | D25: 0 | G25: -343 | H25: =SUM(C25:G25) -> -343
A26: 2400200 | B26: LM ABN AMRO Bank Disposal NL58 ABNA 0818 9180 39 | C26: 1427332 | D26: -1408139 | E26: -18700 | F26: -482 | G26: -11 | H26: =SUM(C26:G26) -> 0
A27: 2400201 | B27: LM ABN AMRO Bank Deposit NL57 ABNA 0541 6205 68 | C27: 1146502 | D27: -1109732 | E27: -19 | F27: -19 | G27: 0 | H27: =SUM(C27:G27) -> 36732
A28: 2400202 | B28: LM ABN AMRO Bank General NL93 ABNA 0541 6132 27 | C28: 743140 | D28: -50664 | E28: -417400 | F28: -13600 | G28: -7131 | H28: =SUM(C28:G28) -> 254345
A29: 2400203 | B29: LM ABN AMRO Bank Maintres NL04 ABNA 0541 6188 06 | C29: 602822 | D29: -159674 | E29: 145814 | F29: -393791 | G29: -99389 | H29: =SUM(C29:G29) -> 95782
A30: 2400204 | B30: LM ABN AMRO Bank Rent NL46 ABNA 0541 6088 35 | C30: 1688207 | D30: -420964 | E30: -850699 | F30: 550068 | G30: 854946 | H30: =SUM(C30:G30) -> 1821558
A31: 2400205 | B31: LM ABN AMRO Bank SR EXP NL88 ABNA 0541 6205 92 | C31: 310037 | D31: -265290 | E31: 133175 | F31: -125945 | G31: 61378 | H31: =SUM(C31:G31) -> 113355
A32: Totaal Liquide middelen
A34: 1000002 | B34: EV Normale aandelen Saldo | C34: -1 | F34: 0 | G34: 0 | H34: =SUM(C34:G34) -> -1
A35: 1100000 | B35: EV Agioreserve Agio aandelen | C35: -19331219 | D35: 100000 | F35: 0 | G35: 0 | H35: =SUM(C35:G35) -> -19231219
A36: 1160000 | B36: EV Overige reserve Reserve aandelen | C36: 11155611 | F36: 0 | G36: 0 | H36: =SUM(C36:G36) -> 11155611
A37: 1160100 | B37: EV Overige reserve Dividenduitkeringen aandelen | C37: 2566438 | D37: 1297717 | E37: 207000 | F37: 0 | G37: 0 | H37: =SUM(C37:G37) -> 4071155
A38: Totaal Eigen vermogen
A40: 1930001 | B40: LLS Hoofdsom ABN AMRO Bank NV Senior Facility Agreement | C40: -130000000 | D40: 0 | E40: 0 | F40: 0 | G40: 0 | H40: =SUM(C40:G40) -> -130000000
A41: 1930101 | B41: LLS Cum aflossingen ABN AMRO Bank NV Senior Facility Agreement | C41: 13224544 | D41: 3569138 | E41: 1387184 | F41: 1984184 | G41: 1540803 | H41: =SUM(C41:G41) -> 21705853
A42: Totaal Langlopende schulden
A44: 2730000 | B44: KLS Crediteuren | C44: -212218 | D44: 900 | F44: -256418.18 | G44: 37465.18 | H44: =SUM(C44:G44) -> -430271
A45: 2730001 | B45: KLS Crediteuren intercompany | C45: 0 | D45: 0 | E45: 0 | F45: 0 | G45: 0 | H45: =SUM(C45:G45) -> 0
A46: Totaal Crediteuren
A48: 2512100 | B48: BEL Afgedragen/ontvangen BTW | C48: -3913 | D48: 271 | E48: -22 | F48: 2114 | G48: 1550 | H48: =SUM(C48:G48) -> 0
A49: 2530000 | B49: BEL Te betalen vennootschapsbelasting | C49: 0 | D49: 0 | E49: 0 | F49: 0 | G49: 0 | H49: =SUM(C49:G49) -> 0
...

Sheet BDO - Q2 2021
C1: Eindbalans per 30-06-2020 | D1: Mutaties Q3 2020 | E1: Mutaties Q4 2020 | F1: Mutaties Q1 2021 | G1: Mutaties Q2 2021 | H1: Saldi per 30-06-2021 | K1: Mutaties Q4 2020 | L1: Mutaties Q1 2021 | M1: Mutaties Q2 2021
A3: Balans
A4: 1600200 | B4: VG Vastgoedbeleggingen Verkrijgings- of vervaardigingsprijs | C4: 129706535 | H4: =SUM(C4:G4)-4048750 -> 125657785 | K4: 977050 | L4: 172507 | M4: 238485
A5: 1600200 | B5: VG Vastgoedbeleggingen Cum afschrijvingen en waardeverm | C5: -11587205 | D5: -653151 | E5: -683661 | F5: -277132 | G5: -667313 | H5: =SUM(C5:G5) -> -13868462
A6: 1610803 | B6: VG Comm VG in exploitatie Buitengebruikstellingen aanschaffingswaarde | C6: -2027956 | D6: -947310 | E6: -1073484 | F6: -706761 | G6: -1597299 | H6: =SUM(C6:G6)+4048750 -> -2304060
A7: 1611003 | B7: VG Comm VG in exploitatie Buitengebruikstellingen cum. afschr. en waardeverm. | C7: 176623 | D7: 90299 | E7: 110448 | F7: -303581 | G7: 170229 | H7: =SUM(C7:G7) -> 244018
A8: Totaal Vastgoedbeleggingen
A10: 1790002 | B10: FVA Latente belastingvordering langlopend | C10: 2814439 | D10: 118583 | E10: 631191 | F10: 142740 | G10: 120923 | H10: =SUM(C10:G10) -> 3827876
A11: Totaal Financiële vaste activa
A13: 2000000 | B13: VOR Debiteuren | C13: 85120 | D13: 316526 | E13: -108371 | F13: -341343 | G13: 281344 | H13: =SUM(C13:G13) -> 233276
A14: 2000300 | B14: VOR Voorziening dubieuze debiteuren | C14: -55541 | E14: 23626 | F14: 0 | G14: 0 | H14: =SUM(C14:G14) -> -31915
A15: Totaal Debiteuren
A17: 2640000 | B17: RC Kortlopend DMRRP INV - I BV | C17: -1913400 | D17: 1642583 | E17: -859900 | F17: 436656 | G17: 550984 | H17: =SUM(C17:G17) -> -143077
A18: Totaal Rekening-courant aandeelhouder
A20: 2040200 | B20: VOR Te vorderen waarborgsommen kortlopen | C20: 5000 | D20: 0 | E20: 0 | F20: 0 | G20: 0 | H20: =SUM(C20:G20) -> 5000
A21: 2040700 | B21: VOR Vooruitbetaalde servicekosten | C21: 3818 | E21: -1022 | F21: -2796 | G21: 0 | H21: =SUM(C21:G21) -> 0
A22: 2040900 | B22: VOR Vooruitbetaalde overige kosten | C22: 295508 | D22: -139615 | E22: -155413 | F22: 342768 | G22: -114416 | H22: =SUM(C22:G22) -> 228832
A23: Totaal overige vorderingen
A25: 2300000 | B25: LM Kruisposten | C25: 0 | F25: -343 | G25: -3777 | H25: =SUM(C25:G25) -> -4120
A26: 2400200 | B26: LM ABN AMRO Bank Disposal NL58 ABNA 0818 9180 39 | C26: 19193 | D26: -18700 | E26: -482 | F26: -11 | G26: 0 | H26: =SUM(C26:G26) -> 0
A27: 2400201 | B27: LM ABN AMRO Bank Deposit NL57 ABNA 0541 6205 68 | C27: 36770 | D27: -19 | E27: -19 | F27: -19 | G27: -19 | H27: =SUM(C27:G27) -> 36694
A28: 2400202 | B28: LM ABN AMRO Bank General NL93 ABNA 0541 6132 27 | C28: 692476 | D28: -417400 | E28: -13600 | F28: -7131 | G28: -37180 | H28: =SUM(C28:G28) -> 217165
A29: 2400203 | B29: LM ABN AMRO Bank Maintres NL04 ABNA 0541 6188 06 | C29: 443148 | D29: 145814 | E29: -393791 | F29: -99389 | G29: 8473 | H29: =SUM(C29:G29) -> 104255
A30: 2400204 | B30: LM ABN AMRO Bank Rent NL46 ABNA 0541 6088 35 | C30: 1267243 | D30: -850699 | E30: 550068 | F30: 854946 | G30: -722443 | H30: =SUM(C30:G30) -> 1099115
A31: 2400205 | B31: LM ABN AMRO Bank SR EXP NL88 ABNA 0541 6205 92 | C31: 44747 | D31: 133175 | E31: -125945 | F31: 61378 | G31: -72522 | H31: =SUM(C31:G31) -> 40833
A32: Totaal Liquide middelen
A34: 1000002 | B34: EV Normale aandelen Saldo | C34: -1 | E34: 0 | F34: 0 | H34: =SUM(C34:G34) -> -1
A35: 1100000 | B35: EV Agioreserve Agio aandelen | C35: -19231219 | E35: 0 | F35: 0 | H35: =SUM(C35:G35) -> -19231219
A36: 1160000 | B36: EV Overige reserve Reserve aandelen | C36: =9733381+3864155 -> 13597536 | E36: 0 | F36: 0 | H36: =SUM(C36:G36) -> 13597536
A37: 1160100 | B37: EV Overige reserve Dividenduitkeringen aandelen | C37: 0 | D37: 207000 | E37: 0 | F37: 0 | G37: 2200000 | H37: =SUM(C37:G37) -> 2407000
A38: Totaal Eigen vermogen
A40: 1930001 | B40: LLS Hoofdsom ABN AMRO Bank NV Senior Facility Agreement | C40: -130000000 | D40: 0 | E40: 0 | F40: 0 | G40: 0 | H40: =SUM(C40:G40) -> -130000000
A41: 1930101 | B41: LLS Cum aflossingen ABN AMRO Bank NV Senior Facility Agreement | C41: 16793682 | D41: 1387184 | E41: 1984184 | F41: 1540803 | G41: 2253796 | H41: =SUM(C41:G41) -> 23959649
A42: Totaal Langlopende schulden
A44: 2730000 | B44: KLS Crediteuren | C44: -211318 | E44: =-342182+85763.82 -> -256418.18 | F44: =123229-85763.82 -> 37465.18 | G44: 411485 | H44: =SUM(C44:G44) -> -18786
A45: 2730001 | B45: KLS Crediteuren intercompany | C45: 0 | D45: 0 | E45: 0 | F45: 0 | G45: 0 | H45: =SUM(C45:G45) -> 0
A46: Totaal Crediteuren
A48: 2512100 | B48: BEL Afgedragen/ontvangen BTW | C48: -3642 | D48: -22 | E48: 2114 | F48: 1550 | G48: -3898 | H48: =SUM(C48:G48) -> -3898
A49: 2530000 | B49: BEL Te betalen vennootschapsbelasting | C49: 0 | D49: 0 | E49: 0 | F49: 0 | G49: 0 | H49: =SUM(C49:G49) -> 0
A50: 2550000 | B50: BEL Te betalen overige belastingen | C50: 0 | D50: 0 | E50: 0 | F50: 0 | G50: 0 | H50: =SUM(C50:G50) -> 0
...

Sheet BDO - Q3 2021
C1: Eindbalans per 30-09-2020 | D1: Mutaties Q4 2020 | E1: Mutaties Q1 2021 | F1: Mutaties Q2 2021 | G1: Mutaties Q3 2021 | H1: Saldi per 30-09-2021 | J1: Mutaties Q4 2020 | K1: Mutaties Q1 2021 | L1: Mutaties Q2 2021 | M1: Mutaties Q3 2021
A3: Balans
A4: 1600200 | B4: VG Vastgoedbeleggingen Verkrijgings- of vervaardigingsprijs | C4: 129706535 | H4: =SUM(C4:G4) -> 129706535 | J4: 977050 | K4: 172507 | L4: 238485 | M4: 230282.95
A5: 1600200 | B5: VG Vastgoedbeleggingen Cum afschrijvingen en waardeverm | C5: -12240356 | D5: -683661 | E5: -277132 | F5: -667313 | G5: -666766 | H5: =SUM(C5:G5) -> -14535228
A6: 1610803 | B6: VG Comm VG in exploitatie Buitengebruikstellingen aanschaffingswaarde | C6: -2975266 | D6: -1073484 | E6: -706761 | F6: -1597299 | G6: -144749 | H6: =SUM(C6:G6) -> -6497559
A7: 1611003 | B7: VG Comm VG in exploitatie Buitengebruikstellingen cum. afschr. en waardeverm. | C7: 266922 | D7: 110448 | E7: -303581 | F7: 170229 | G7: 16814 | H7: =SUM(C7:G7) -> 260832
A8: Totaal Vastgoedbeleggingen
A10: 1790002 | B10: FVA Latente belastingvordering langlopend | C10: 2933022 | D10: 631191 | E10: 142740 | F10: 120923 | G10: 161798 | H10: =SUM(C10:G10) -> 3989674
A11: Totaal Financiële vaste activa
A13: 2000000 | B13: VOR Debiteuren | C13: 401646 | D13: -108371 | E13: -341343 | F13: 281344 | G13: =748300.39+144357.64 -> 892658.03 | H13: =SUM(C13:G13) -> 1125934
B14: Vooruitontvangen op debiteuren | C14: 0 | D14: 0 | E14: 0 | F14: 0 | G14: -144357.64 | H14: =SUM(C14:G14) -> -144357.64
A15: 2000300 | B15: VOR Voorziening dubieuze debiteuren | C15: -55541 | D15: 23626 | E15: 0 | F15: 0 | G15: 0 | H15: =SUM(C15:G15) -> -31915
A16: Totaal Debiteuren | H16: =SUM(C16:G16) -> 0
H17: =SUM(C17:G17) -> 0
A18: 2640000 | B18: RC Kortlopend DMRRP INV - I BV | C18: -270817 | D18: -859900 | E18: 436656 | F18: 550984 | G18: 1407409 | H18: =SUM(C18:G18) -> 1264332
A19: Totaal Rekening-courant aandeelhouder | H19: =SUM(C19:G19) -> 0
H20: =SUM(C20:G20) -> 0
A21: 2040200 | B21: VOR Te vorderen waarborgsommen kortlopen | C21: 5000 | D21: 0 | E21: 0 | F21: 0 | G21: 0 | H21: =SUM(C21:G21) -> 5000
A22: 2040500 | B22: VOR Vooruitbetaalde verzekeringen | C22: 0 | D22: 0 | E22: -14411 | F22: 70849 | G22: -28219.3 | H22: =SUM(C22:G22) -> 28218.7
A23: 2040700 | B23: VOR Vooruitbetaalde servicekosten | C23: 3818 | D23: -1022 | E23: -2796 | F23: 0 | G23: 0 | H23: =SUM(C23:G23) -> 0
A24: 2040900 | B24: VOR Vooruitbetaalde overige kosten | C24: 155893 | D24: -155413 | E24: 198503.49 | F24: -251330.51 | G24: 311027.5 | H24: =SUM(C24:G24) -> 258680.48 | I24: Correctie betreft waterschapsbelasting, welke in Q3 betaald is over de hele periode van 2021. Deze kosten zijn verdeeld over 4 kwartalen.
A25: Totaal overige vorderingen | H25: =SUM(C25:G25) -> 0
H26: =SUM(C26:G26) -> 0
A27: 2300000 | B27: LM Kruisposten | C27: 0 | D27: 0 | E27: -343 | F27: -3777 | G27: -12957.2 | H27: =SUM(C27:G27) -> -17077.2
A28: 2400200 | B28: LM ABN AMRO Bank Disposal NL58 ABNA 0818 9180 39 | C28: 493 | D28: -482 | E28: -11 | F28: 0 | G28: 0.91 | H28: =SUM(C28:G28) -> 0.91
